INFO:httpx:HTTP Request: GET http://localhost:8005/.well-known/agent-card.json "HTTP/1.1 200 OK"
INFO:a2a.client.card_resolver:Successfully fetched agent card data from http://localhost:8005/.well-known/agent-card.json: {'capabilities': {'pushNotifications': False, 'stateTransitionHistory': False, 'streaming': False}, 'defaultInputModes': ['text', 'text/plain'], 'defaultOutputModes': ['text', 'application/json'], 'description': 'Generates HTML and Markdown documents from user queries using LLM and MCP servers', 'name': 'Document Generator Agent', 'preferredTransport': 'JSONRPC', 'protocolVersion': '0.3.0', 'skills': [{'description': 'Generate comprehensive HTML documents from user queries using LLM', 'examples': ['Create an HTML page about quantum computing', 'Generate HTML documentation for Python functions', 'Make an HTML guide for beginners'], 'id': 'generate_html', 'name': 'HTML Document Generation', 'tags': ['html', 'document', 'generation', 'llm']}, {'description': 'Generate well-structured Markdown documents from user queries using LLM', 'examples': ['Create a markdown guide for Python beginners', 'Generate markdown documentation for APIs', 'Make a markdown tutorial about machine learning'], 'id': 'generate_markdown', 'name': 'Markdown Document Generation', 'tags': ['markdown', 'document', 'generation', 'llm']}, {'description': 'Convert documents between different formats (HTML, Markdown, PDF, etc.) using Pandoc', 'examples': ['Convert this HTML to Markdown', 'Generate a PDF version of this document', 'Convert Markdown to HTML with better formatting'], 'id': 'mcp_mcp_pandoc', 'name': 'Document Format Conversion', 'tags': ['pandoc', 'conversion', 'format', 'mcp']}], 'url': 'http://localhost:8005/', 'version': '1.0.0'}
C:\Users\User\PycharmProjects\agent-document-generator\simple_test.py:30: DeprecationWarning: A2AClient is deprecated and will be removed in a future version. Use ClientFactory to create a client with a JSON-RPC transport.
  client = A2AClient(httpx_client=httpx_client, agent_card=agent_card)
ERROR:__main__:Error: Timeout Error: Client Request timed out
Traceback (most recent call last):
  File "C:\Users\User\AppData\Roaming\Python\Python313\site-packages\httpx\_transports\default.py", line 101, in map_httpcore_exceptions
    yield
  File "C:\Users\User\AppData\Roaming\Python\Python313\site-packages\httpx\_transports\default.py", line 394, in handle_async_request
    resp = await self._pool.handle_async_request(req)
           ^^^^^^^^^^^^^^^^^^^^^^^^^^^^^^^^^^^^^^^^^^
  File "C:\Users\User\AppData\Roaming\Python\Python313\site-packages\httpcore\_async\connection_pool.py", line 256, in handle_async_request
    raise exc from None
  File "C:\Users\User\AppData\Roaming\Python\Python313\site-packages\httpcore\_async\connection_pool.py", line 236, in handle_async_request
    response = await connection.handle_async_request(
               ^^^^^^^^^^^^^^^^^^^^^^^^^^^^^^^^^^^^^^
        pool_request.request
        ^^^^^^^^^^^^^^^^^^^^
    )
    ^
  File "C:\Users\User\AppData\Roaming\Python\Python313\site-packages\httpcore\_async\connection.py", line 103, in handle_async_request
    return await self._connection.handle_async_request(request)
           ^^^^^^^^^^^^^^^^^^^^^^^^^^^^^^^^^^^^^^^^^^^^^^^^^^^^
  File "C:\Users\User\AppData\Roaming\Python\Python313\site-packages\httpcore\_async\http11.py", line 136, in handle_async_request
    raise exc
  File "C:\Users\User\AppData\Roaming\Python\Python313\site-packages\httpcore\_async\http11.py", line 106, in handle_async_request
    ) = await self._receive_response_headers(**kwargs)
        ^^^^^^^^^^^^^^^^^^^^^^^^^^^^^^^^^^^^^^^^^^^^^^
  File "C:\Users\User\AppData\Roaming\Python\Python313\site-packages\httpcore\_async\http11.py", line 177, in _receive_response_headers
    event = await self._receive_event(timeout=timeout)
            ^^^^^^^^^^^^^^^^^^^^^^^^^^^^^^^^^^^^^^^^^^
  File "C:\Users\User\AppData\Roaming\Python\Python313\site-packages\httpcore\_async\http11.py", line 217, in _receive_event
    data = await self._network_stream.read(
           ^^^^^^^^^^^^^^^^^^^^^^^^^^^^^^^^
        self.READ_NUM_BYTES, timeout=timeout
        ^^^^^^^^^^^^^^^^^^^^^^^^^^^^^^^^^^^^
    )
    ^
  File "C:\Users\User\AppData\Roaming\Python\Python313\site-packages\httpcore\_backends\anyio.py", line 32, in read
    with map_exceptions(exc_map):
         ~~~~~~~~~~~~~~^^^^^^^^^
  File "C:\Python313\Lib\contextlib.py", line 162, in __exit__
    self.gen.throw(value)
    ~~~~~~~~~~~~~~^^^^^^^
  File "C:\Users\User\AppData\Roaming\Python\Python313\site-packages\httpcore\_exceptions.py", line 14, in map_exceptions
    raise to_exc(exc) from exc
httpcore.ReadTimeout

The above exception was the direct cause of the following exception:

Traceback (most recent call last):
  File "C:\Users\User\AppData\Roaming\Python\Python313\site-packages\a2a\client\transports\jsonrpc.py", line 184, in _send_request
    response = await self.httpx_client.post(
               ^^^^^^^^^^^^^^^^^^^^^^^^^^^^^
        self.url, json=rpc_request_payload, **(http_kwargs or {})
        ^^^^^^^^^^^^^^^^^^^^^^^^^^^^^^^^^^^^^^^^^^^^^^^^^^^^^^^^^
    )
    ^
  File "C:\Users\User\AppData\Roaming\Python\Python313\site-packages\httpx\_client.py", line 1859, in post
    return await self.request(
           ^^^^^^^^^^^^^^^^^^^
    ...<13 lines>...
    )
    ^
  File "C:\Users\User\AppData\Roaming\Python\Python313\site-packages\httpx\_client.py", line 1540, in request
    return await self.send(request, auth=auth, follow_redirects=follow_redirects)
           ^^^^^^^^^^^^^^^^^^^^^^^^^^^^^^^^^^^^^^^^^^^^^^^^^^^^^^^^^^^^^^^^^^^^^^
  File "C:\Users\User\AppData\Roaming\Python\Python313\site-packages\httpx\_client.py", line 1629, in send
    response = await self._send_handling_auth(
               ^^^^^^^^^^^^^^^^^^^^^^^^^^^^^^^
    ...<4 lines>...
    )
    ^
  File "C:\Users\User\AppData\Roaming\Python\Python313\site-packages\httpx\_client.py", line 1657, in _send_handling_auth
    response = await self._send_handling_redirects(
               ^^^^^^^^^^^^^^^^^^^^^^^^^^^^^^^^^^^^
    ...<3 lines>...
    )
    ^
  File "C:\Users\User\AppData\Roaming\Python\Python313\site-packages\httpx\_client.py", line 1694, in _send_handling_redirects
    response = await self._send_single_request(request)
               ^^^^^^^^^^^^^^^^^^^^^^^^^^^^^^^^^^^^^^^^
  File "C:\Users\User\AppData\Roaming\Python\Python313\site-packages\httpx\_client.py", line 1730, in _send_single_request
    response = await transport.handle_async_request(request)
               ^^^^^^^^^^^^^^^^^^^^^^^^^^^^^^^^^^^^^^^^^^^^^
  File "C:\Users\User\AppData\Roaming\Python\Python313\site-packages\httpx\_transports\default.py", line 393, in handle_async_request
    with map_httpcore_exceptions():
         ~~~~~~~~~~~~~~~~~~~~~~~^^
  File "C:\Python313\Lib\contextlib.py", line 162, in __exit__
    self.gen.throw(value)
    ~~~~~~~~~~~~~~^^^^^^^
  File "C:\Users\User\AppData\Roaming\Python\Python313\site-packages\httpx\_transports\default.py", line 118, in map_httpcore_exceptions
    raise mapped_exc(message) from exc
httpx.ReadTimeout

The above exception was the direct cause of the following exception:

Traceback (most recent call last):
  File "C:\Users\User\PycharmProjects\agent-document-generator\simple_test.py", line 47, in simple_test
    response = await client.send_message(request)
               ^^^^^^^^^^^^^^^^^^^^^^^^^^^^^^^^^^
  File "C:\Users\User\AppData\Roaming\Python\Python313\site-packages\a2a\client\legacy.py", line 86, in send_message
    result = await self._transport.send_message(
             ^^^^^^^^^^^^^^^^^^^^^^^^^^^^^^^^^^^
        request.params, context=context
        ^^^^^^^^^^^^^^^^^^^^^^^^^^^^^^^
    )
    ^
  File "C:\Users\User\AppData\Roaming\Python\Python313\site-packages\a2a\utils\telemetry.py", line 194, in async_wrapper
    result = await func(*args, **kwargs)
             ^^^^^^^^^^^^^^^^^^^^^^^^^^^
  File "C:\Users\User\AppData\Roaming\Python\Python313\site-packages\a2a\client\transports\jsonrpc.py", line 125, in send_message
    response_data = await self._send_request(payload, modified_kwargs)
                    ^^^^^^^^^^^^^^^^^^^^^^^^^^^^^^^^^^^^^^^^^^^^^^^^^^
  File "C:\Users\User\AppData\Roaming\Python\Python313\site-packages\a2a\utils\telemetry.py", line 194, in async_wrapper
    result = await func(*args, **kwargs)
             ^^^^^^^^^^^^^^^^^^^^^^^^^^^
  File "C:\Users\User\AppData\Roaming\Python\Python313\site-packages\a2a\client\transports\jsonrpc.py", line 190, in _send_request
    raise A2AClientTimeoutError('Client Request timed out') from e
a2a.client.errors.A2AClientTimeoutError: Timeout Error: Client Request timed out
Agent: Document Generator Agent
Skills: 3
Sending message...
